<?xml version='1.0'?>
<sdf version='1.4'>
  <model name="fred">
    <static>false</static>
    <link name='chassis'>
      <pose>0 0 .1774 0 0 0</pose>

      <inertial>
        <mass>7.0</mass>
        <inertia> <!-- inertias are tricky to compute -->
          <!-- http://gazebosim.org/tutorials?tut=inertia&cat=build_robot -->
          <ixx>0.0675</ixx>       <!-- for a box: ixx = 0.083 * mass * (y*y + z*z) -->
          <ixy>0.0</ixy>         <!-- for a box: ixy = 0 -->
          <ixz>0.0</ixz>         <!-- for a box: ixz = 0 -->
          <iyy>0.0675</iyy>       <!-- for a box: iyy = 0.083 * mass * (x*x + z*z) -->
          <iyz>0.0</iyz>         <!-- for a box: iyz = 0 -->
          <izz>0.108</izz>       <!-- for a box: izz = 0.083 * mass * (x*x + y*y) -->
        </inertia>
      </inertial>

      <collision name='collision'>
        <geometry>
          <box>
            <size>.3048 .3048 .1524</size>
          </box>
        </geometry>
      </collision>

      <visual name='visual'>
        <geometry>
          <box>
            <size>.3048 .3048 .1524</size>
          </box>
        </geometry>
      </visual>
      
      <collision name='tail_collision'>
        <pose>-.1524 0 -.0762 0 0 0</pose>
        <geometry>
          <polyline>
            <point>0 -.1524</point>
            <point>0 .1524</point>
            <point>-.1016 0</point>
            <height>.025</height>
          </polyline>
        </geometry>
      </collision>
      
      <visual name='tail_visual'>
        <pose>-.1524 0 -.0762 0 0 0</pose>
        <geometry>
          <polyline>
            <point>0 -.1524</point>
            <point>0 .1524</point>
            <point>-.1016 0</point>
            <height>.025</height>
          </polyline>
        </geometry>
      </visual>
      
      <collision name='caster_collision'>
        <pose>-0.229 0 -0.1012 0 0 0</pose>
        <geometry>
            <sphere>
            <radius>.025</radius>
          </sphere>
        </geometry>

        <surface>
          <friction>
            <ode>
              <mu>0</mu>
              <mu2>0</mu2>
              <slip1>1.0</slip1>
              <slip2>1.0</slip2>
            </ode>
          </friction>
        </surface>
      </collision>

      <visual name='caster_visual'>
        <pose>-0.229 0 -0.1012 0 0 0</pose>
        <geometry>
          <sphere>
            <radius>.025</radius>
          </sphere>
        </geometry>
      </visual>
    </link>
    
    <link name="left_wheel">
      <pose>.1016 .1624 0.1132 0 1.5707 1.5707</pose>
      <collision name="collision">
        <geometry>
          <cylinder>
            <radius>.0635</radius>
            <length>.02</length>
          </cylinder>
        </geometry>
        <surface>
          <friction>
            <ode>
              <mu>1.0</mu>
              <mu2>1.0</mu2>
            </ode>
          </friction>
        </surface>
      </collision>
      <visual name="visual">
        <geometry>
          <cylinder>
            <radius>.0635</radius>
            <length>.02</length>
          </cylinder>
        </geometry>
      </visual>
    </link>
    
    <link name="right_wheel">
      <pose>.1016 -.1624 0.1132 0 1.5707 1.5707</pose>
      <collision name="collision">
        <geometry>
          <cylinder>
            <radius>.0635</radius>
            <length>.02</length>
          </cylinder>
        </geometry>
        <surface>
          <friction>
            <ode>
              <mu>1.0</mu>
              <mu2>1.0</mu2>
            </ode>
          </friction>
        </surface>
      </collision>
      <visual name="visual">
        <geometry>
          <cylinder>
            <radius>.0635</radius>
            <length>.02</length>
          </cylinder>
        </geometry>
      </visual>
    </link>
    
    <joint type="revolute" name="left_wheel_joint">
      <pose>0 0 0.381 0 0 0</pose>
      <child>left_wheel</child>
      <parent>chassis</parent>
      <axis>
        <xyz>0 1 0</xyz>
      </axis>
    </joint>

    <joint type="revolute" name="right_wheel_joint">
      <pose>0 0 -0.381 3.14159 0 0</pose>
      <child>right_wheel</child>
      <parent>chassis</parent>
      <axis>
        <xyz>0 1 0</xyz>
      </axis>
    </joint>
    
    <joint type="fixed" name="range_joint">
      <axis>
        <xyz>0 1 0</xyz>
      </axis>
      <pose> 0 0 0 0 0 0 </pose>
      <parent>chassis</parent>
      <child>radar_link</child>
    </joint>
    
    <joint type="fixed" name="camera_joint">
      <axis>
        <xyz>0 1 0</xyz>
      </axis>
      <pose> 0 0 0 0 0 0 </pose>
      <parent>chassis</parent>
      <child>camera_link</child>
    </joint>
    
    <joint type="fixed" name="thermal_array0_joint">
      <axis>
        <xyz>0 1 0</xyz>
      </axis>
      <pose> 0 0 0 0 0 0 </pose>
      <parent>chassis</parent>
      <child>thermal_array0_link</child>
    </joint>
    
    <joint type="fixed" name="thermal_array1_joint">
      <axis>
        <xyz>0 1 0</xyz>
      </axis>
      <pose> 0 0 0 0 0 0 </pose>
      <parent>chassis</parent>
      <child>thermal_array1_link</child>
    </joint>
    
    <joint type="fixed" name="thermal_array2_joint">
      <axis>
        <xyz>0 1 0</xyz>
      </axis>
      <pose> 0 0 0 0 0 0 </pose>
      <parent>chassis</parent>
      <child>thermal_array2_link</child>
    </joint>
    
    <link name="radar_link">
      <collision name="collision">
        <pose> .1524 -0.02 .1524 0 0 0 </pose>
        <geometry>
          <box>
            <size>.01 .01 .01</size>
          </box>
        </geometry>
      </collision>
      <visual name="visual">
        <pose> .1524 -0.02 .1524 0 0 0 </pose>
        <geometry>
          <box>
            <size>.01 .01 .01</size>
          </box>
        </geometry>
      </visual>

      <sensor type="ray" name="radar">
          <pose>.1524 -0.02 .1524 0 0 0</pose>
          <update_rate>5</update_rate>
          <ray>
            <scan>
              <horizontal>
                <samples>5</samples>
                <resolution>1.0</resolution>
                <min_angle>-0.25</min_angle>
                <max_angle>0.25</max_angle>
              </horizontal>
              <vertical>
                <samples>5</samples>
                <resolution>1</resolution>
                <min_angle>-0.25</min_angle>
                <max_angle>0.25</max_angle>
              </vertical>
            </scan>
            <range>
              <min>0.20</min>
              <max>1.0</max>
              <resolution>0.001</resolution>
            </range>
          </ray>
          <plugin filename="libgazebo_ros_range.so" name="gazebo_ros_radar">
            <gaussianNoise>0.005</gaussianNoise>
            <alwaysOn>true</alwaysOn>
            <updateRate>5</updateRate>
            <topicName>radar</topicName>
            <frameName>radar_link</frameName>
            <fov>0.5</fov>
            <radiation>infrared</radiation>
          </plugin>
      </sensor>
    </link>

    <link name="camera_link">
      <collision name="collision">
        <pose> .1524 0 .1524 0 0 0 </pose>
        <geometry>
          <box>
            <size>.01 .01 .01</size>
          </box>
        </geometry>
      </collision>
      <visual name="visual">
        <pose> .1524 0 .1524 0 0 0 </pose>
        <geometry>
          <box>
            <size>.01 .01 .01</size>
          </box>
        </geometry>
      </visual>
      
      <sensor type="camera" name="camera">
          <pose>.1524 0 .1524 0 0 0</pose>
          <update_rate>5</update_rate>
          <camera name="camera">
            <horizontal_fov>1.3962634</horizontal_fov>
            <image>
              <width>800</width>
              <height>800</height>
              <format>R8G8B8</format>
            </image>
            <clip>
              <near>0.02</near>
              <far>300</far>
            </clip>
            <noise>
              <type>gaussian</type>
              <!-- Noise is sampled independently per pixel on each frame.
                   That pixel's noise value is added to each of its color
                   channels, which at that point lie in the range [0,1]. -->
              <mean>0.0</mean>
              <stddev>0.007</stddev>
            </noise>
          </camera>
          <plugin filename="libgazebo_ros_camera.so" name="gazebo_ros_camera">
            <alwaysOn>true</alwaysOn>
            <updateRate>5</updateRate>
            <cameraName>fred/camera</cameraName>
            <imageTopicName>camera</imageTopicName>
            <frameName>camera_link</frameName>
            <hackBaseline>0.07</hackBaseline>
            <distortionK1>0.0</distortionK1>
            <distortionK2>0.0</distortionK2>
            <distortionK3>0.0</distortionK3>
            <distortionT1>0.0</distortionT1>
            <distortionT2>0.0</distortionT2>
          </plugin>
      </sensor>
    </link>
    
    
    <link name="thermal_array0_link">
      <collision name="collision">
        <pose> 0 .1524 .1524 0 0 1.5708 </pose>
        <geometry>
          <box>
            <size>.01 .01 .01</size>
          </box>
        </geometry>
      </collision>
      <visual name="visual">
        <pose> 0 .1524 .1524 0 0 1.5708 </pose>
        <geometry>
          <box>
            <size>.01 .01 .01</size>
          </box>
        </geometry>
      </visual>
      
      <sensor type="camera" name="thermal_array0">
          <pose>0 .1524 .1524 0 0 1.5708</pose>
          <update_rate>5</update_rate>
          <camera name="thermal_array0">
            <horizontal_fov>1.3962634</horizontal_fov>
            <image>
              <width>800</width>
              <height>800</height>
              <format>R8G8B8</format>
            </image>
            <clip>
              <near>0.02</near>
              <far>300</far>
            </clip>
            <noise>
              <type>gaussian</type>
              <mean>0.0</mean>
              <stddev>0.007</stddev>
            </noise>
          </camera>
          <plugin filename="libgazebo_ros_camera.so" name="gazebo_thermal_array0">
            <alwaysOn>true</alwaysOn>
            <updateRate>5</updateRate>
            <cameraName>fred/thermal_array0</cameraName>
            <imageTopicName>thermal_array0</imageTopicName>
            <frameName>thermal_array0_link</frameName>
            <hackBaseline>0.07</hackBaseline>
            <distortionK1>0.0</distortionK1>
            <distortionK2>0.0</distortionK2>
            <distortionK3>0.0</distortionK3>
            <distortionT1>0.0</distortionT1>
            <distortionT2>0.0</distortionT2>
          </plugin>
      </sensor>
    </link>
    
    
    <link name="thermal_array1_link">
      <collision name="collision">
        <pose> .1524 0.02 .1524 0 0 0 </pose>
        <geometry>
          <box>
            <size>.01 .01 .01</size>
          </box>
        </geometry>
      </collision>
      <visual name="visual">
        <pose> .1524 0.02 .1524 0 0 0 </pose>
        <geometry>
          <box>
            <size>.01 .01 .01</size>
          </box>
        </geometry>
      </visual>
      
      <sensor type="camera" name="thermal_array1">
          <pose>.1524 0.02 .1524 0 0 0</pose>
          <update_rate>5</update_rate>
          <camera name="thermal_array1">
            <horizontal_fov>1.3962634</horizontal_fov>
            <image>
              <width>800</width>
              <height>800</height>
              <format>R8G8B8</format>
            </image>
            <clip>
              <near>0.02</near>
              <far>300</far>
            </clip>
            <noise>
              <type>gaussian</type>
              <mean>0.0</mean>
              <stddev>0.007</stddev>
            </noise>
          </camera>
          <plugin filename="libgazebo_ros_camera.so" name="gazebo_thermal_array1">
            <alwaysOn>true</alwaysOn>
            <updateRate>5</updateRate>
            <cameraName>fred/thermal_array1</cameraName>
            <imageTopicName>thermal_array1</imageTopicName>
            <frameName>thermal_array1_link</frameName>
            <hackBaseline>0.07</hackBaseline>
            <distortionK1>0.0</distortionK1>
            <distortionK2>0.0</distortionK2>
            <distortionK3>0.0</distortionK3>
            <distortionT1>0.0</distortionT1>
            <distortionT2>0.0</distortionT2>
          </plugin>
      </sensor>
    </link>
    
    
    <!--
    Will want to have this third thermal array at some point, but right now
    there is something bad in the syntax I can't figure out and it causes
    fred not to spawn in Gazebo
    
    <link name="thermal_array2_link">
      <collision name="collision">
        <pose> 0 -.1524 .1524 0 0 1.5708 </pose>
        <geometry>
          <box>
            <size>.01 .01 .01</size>
          </box>
        </geometry>
      </collision>
      <visual name="visual">
        <pose> 0 -.1524 .1524 0 0 1.5708 </pose>
        <geometry>
          <box>
            <size>.01 .01 .01</size>
          </box>
        </geometry>
      </visual>
      
      <sensor type="camera" name="thermal_array2">
          <pose>0 -.1524 .1524 0 0 1.5708</pose>
          <update_rate>5</update_rate>
          <camera name="thermal_array2">
            <horizontal_fov>1.3962634</horizontal_fov>
            <image>
              <width>800</width>
              <height>800</height>
              <format>R8G8B8</format>
            </image>
            <clip>
              <near>0.02</near>
              <far>300</far>
            </clip>
            <noise>
              <type>gaussian</type>
              <mean>0.0</mean>
              <stddev>0.007</stddev>
            </noise>
          </camera>
          <plugin filename="libgazebo_ros_camera.so" name="gazebo_thermal_array2">
            <alwaysOn>true</alwaysOn>
            <updateRate>5</updateRate>
            <cameraName>fred/thermal_array2</cameraName>
            <imageTopicName>thermal_array2</imageTopicName>
            <frameName>thermal_array2_link</frameName>
            <hackBaseline>0.07</hackBaseline>
            <distortionK1>0.0</distortionK1>
            <distortionK2>0.0</distortionK2>
            <distortionK3>0.0</distortionK3>
            <distortionT1>0.0</distortionT1>
            <distortionT2>0.0</distortionT2>
          </plugin>
      </sensor>
    </link>
    -->


    <plugin name="differential_drive_controller" filename="libgazebo_ros_diff_drive.so">
      <alwaysOn>true</alwaysOn>
      <updateRate>40</updateRate>
      <leftJoint>left_wheel_joint</leftJoint>
      <rightJoint>right_wheel_joint</rightJoint>
      <wheelSeparation>.3048</wheelSeparation>
      <wheelDiameter>.127</wheelDiameter>
      <torque>10</torque>
      <commandTopic>cmd_vel</commandTopic>
      <odometryTopic>odom</odometryTopic>
      <odometryFrame>odom</odometryFrame>
      <robotBaseFrame>chassis</robotBaseFrame>
      <wheelAcceleration>0</wheelAcceleration>
      <publishOdomTF>true</publishOdomTF>
      <publishWheelJointState>true</publishWheelJointState>
      <odometrySource>world</odometrySource>
    </plugin>
  </model>
</sdf>
